[2023-04-03T08:54:32.350+0000] {taskinstance.py:1083} INFO - Dependencies all met for <TaskInstance: pokeapi_dag.extract_pokemon manual__2023-04-03T08:49:52.831367+00:00 [queued]>
[2023-04-03T08:54:32.354+0000] {taskinstance.py:1083} INFO - Dependencies all met for <TaskInstance: pokeapi_dag.extract_pokemon manual__2023-04-03T08:49:52.831367+00:00 [queued]>
[2023-04-03T08:54:32.355+0000] {taskinstance.py:1279} INFO - 
--------------------------------------------------------------------------------
[2023-04-03T08:54:32.355+0000] {taskinstance.py:1280} INFO - Starting attempt 1 of 2
[2023-04-03T08:54:32.356+0000] {taskinstance.py:1281} INFO - 
--------------------------------------------------------------------------------
[2023-04-03T08:54:32.442+0000] {taskinstance.py:1300} INFO - Executing <Task(PythonOperator): extract_pokemon> on 2023-04-03 08:49:52.831367+00:00
[2023-04-03T08:54:32.447+0000] {standard_task_runner.py:55} INFO - Started process 16243 to run task
[2023-04-03T08:54:32.449+0000] {standard_task_runner.py:82} INFO - Running: ['airflow', 'tasks', 'run', 'pokeapi_dag', 'extract_pokemon', 'manual__2023-04-03T08:49:52.831367+00:00', '--job-id', '486', '--raw', '--subdir', 'DAGS_FOLDER/pokebase_to_s3.py', '--cfg-path', '/tmp/tmpzgt9s6es']
[2023-04-03T08:54:32.450+0000] {standard_task_runner.py:83} INFO - Job 486: Subtask extract_pokemon
[2023-04-03T08:54:32.491+0000] {task_command.py:388} INFO - Running <TaskInstance: pokeapi_dag.extract_pokemon manual__2023-04-03T08:49:52.831367+00:00 [running]> on host 59f4bcb29cab
[2023-04-03T08:54:32.547+0000] {taskinstance.py:1507} INFO - Exporting the following env vars:
AIRFLOW_CTX_DAG_OWNER=airflow
AIRFLOW_CTX_DAG_ID=pokeapi_dag
AIRFLOW_CTX_TASK_ID=extract_pokemon
AIRFLOW_CTX_EXECUTION_DATE=2023-04-03T08:49:52.831367+00:00
AIRFLOW_CTX_TRY_NUMBER=1
AIRFLOW_CTX_DAG_RUN_ID=manual__2023-04-03T08:49:52.831367+00:00
[2023-04-03T08:59:02.937+0000] {taskinstance.py:1768} ERROR - Task failed with exception
Traceback (most recent call last):
  File "/usr/local/lib/python3.10/site-packages/airflow/operators/python.py", line 175, in execute
    return_value = self.execute_callable()
  File "/usr/local/lib/python3.10/site-packages/airflow/operators/python.py", line 192, in execute_callable
    return self.python_callable(*self.op_args, **self.op_kwargs)
  File "/workspaces/data-engineer-zoomcamp-project/airflow/dags/pokebase_to_s3.py", line 70, in extract_pokemon
    s3.put_object(
  File "/home/vscode/.local/lib/python3.10/site-packages/botocore/client.py", line 508, in _api_call
    return self._make_api_call(operation_name, kwargs)
  File "/home/vscode/.local/lib/python3.10/site-packages/botocore/client.py", line 898, in _make_api_call
    http, parsed_response = self._make_request(
  File "/home/vscode/.local/lib/python3.10/site-packages/botocore/client.py", line 921, in _make_request
    return self._endpoint.make_request(operation_model, request_dict)
  File "/home/vscode/.local/lib/python3.10/site-packages/botocore/endpoint.py", line 119, in make_request
    return self._send_request(request_dict, operation_model)
  File "/home/vscode/.local/lib/python3.10/site-packages/botocore/endpoint.py", line 198, in _send_request
    request = self.create_request(request_dict, operation_model)
  File "/home/vscode/.local/lib/python3.10/site-packages/botocore/endpoint.py", line 134, in create_request
    self._event_emitter.emit(
  File "/home/vscode/.local/lib/python3.10/site-packages/botocore/hooks.py", line 412, in emit
    return self._emitter.emit(aliased_event_name, **kwargs)
  File "/home/vscode/.local/lib/python3.10/site-packages/botocore/hooks.py", line 256, in emit
    return self._emit(event_name, kwargs)
  File "/home/vscode/.local/lib/python3.10/site-packages/botocore/hooks.py", line 239, in _emit
    response = handler(**kwargs)
  File "/home/vscode/.local/lib/python3.10/site-packages/botocore/signers.py", line 103, in handler
    return self.sign(operation_name, request)
  File "/home/vscode/.local/lib/python3.10/site-packages/botocore/signers.py", line 187, in sign
    auth.add_auth(request)
  File "/home/vscode/.local/lib/python3.10/site-packages/botocore/auth.py", line 407, in add_auth
    raise NoCredentialsError()
botocore.exceptions.NoCredentialsError: Unable to locate credentials
[2023-04-03T08:59:02.946+0000] {taskinstance.py:1318} INFO - Marking task as UP_FOR_RETRY. dag_id=pokeapi_dag, task_id=extract_pokemon, execution_date=20230403T084952, start_date=20230403T085432, end_date=20230403T085902
[2023-04-03T08:59:02.968+0000] {standard_task_runner.py:100} ERROR - Failed to execute job 486 for task extract_pokemon (Unable to locate credentials; 16243)
[2023-04-03T08:59:03.014+0000] {local_task_job.py:208} INFO - Task exited with return code 1
[2023-04-03T08:59:03.027+0000] {taskinstance.py:2578} INFO - 0 downstream tasks scheduled from follow-on schedule check
