[2023-04-03T10:14:59.343+0000] {taskinstance.py:1083} INFO - Dependencies all met for <TaskInstance: pokeapi_dag.extract_generations manual__2023-04-03T10:12:51.148558+00:00 [queued]>
[2023-04-03T10:14:59.347+0000] {taskinstance.py:1083} INFO - Dependencies all met for <TaskInstance: pokeapi_dag.extract_generations manual__2023-04-03T10:12:51.148558+00:00 [queued]>
[2023-04-03T10:14:59.348+0000] {taskinstance.py:1279} INFO - 
--------------------------------------------------------------------------------
[2023-04-03T10:14:59.348+0000] {taskinstance.py:1280} INFO - Starting attempt 1 of 2
[2023-04-03T10:14:59.349+0000] {taskinstance.py:1281} INFO - 
--------------------------------------------------------------------------------
[2023-04-03T10:14:59.372+0000] {taskinstance.py:1300} INFO - Executing <Task(PythonOperator): extract_generations> on 2023-04-03 10:12:51.148558+00:00
[2023-04-03T10:14:59.375+0000] {standard_task_runner.py:55} INFO - Started process 3738 to run task
[2023-04-03T10:14:59.376+0000] {standard_task_runner.py:82} INFO - Running: ['airflow', 'tasks', 'run', 'pokeapi_dag', 'extract_generations', 'manual__2023-04-03T10:12:51.148558+00:00', '--job-id', '497', '--raw', '--subdir', 'DAGS_FOLDER/pokebase_to_s3.py', '--cfg-path', '/tmp/tmpfywqrhkp']
[2023-04-03T10:14:59.377+0000] {standard_task_runner.py:83} INFO - Job 497: Subtask extract_generations
[2023-04-03T10:14:59.413+0000] {task_command.py:388} INFO - Running <TaskInstance: pokeapi_dag.extract_generations manual__2023-04-03T10:12:51.148558+00:00 [running]> on host 59f4bcb29cab
[2023-04-03T10:14:59.468+0000] {taskinstance.py:1507} INFO - Exporting the following env vars:
AIRFLOW_CTX_DAG_OWNER=airflow
AIRFLOW_CTX_DAG_ID=pokeapi_dag
AIRFLOW_CTX_TASK_ID=extract_generations
AIRFLOW_CTX_EXECUTION_DATE=2023-04-03T10:12:51.148558+00:00
AIRFLOW_CTX_TRY_NUMBER=1
AIRFLOW_CTX_DAG_RUN_ID=manual__2023-04-03T10:12:51.148558+00:00
[2023-04-03T10:14:59.669+0000] {taskinstance.py:1768} ERROR - Task failed with exception
Traceback (most recent call last):
  File "/usr/local/lib/python3.10/site-packages/airflow/operators/python.py", line 175, in execute
    return_value = self.execute_callable()
  File "/usr/local/lib/python3.10/site-packages/airflow/operators/python.py", line 192, in execute_callable
    return self.python_callable(*self.op_args, **self.op_kwargs)
  File "/workspaces/data-engineer-zoomcamp-project/airflow/dags/pokebase_to_s3.py", line 110, in extract_generations
    s3.put_object(
NameError: name 's3' is not defined
[2023-04-03T10:14:59.676+0000] {taskinstance.py:1318} INFO - Marking task as UP_FOR_RETRY. dag_id=pokeapi_dag, task_id=extract_generations, execution_date=20230403T101251, start_date=20230403T101459, end_date=20230403T101459
[2023-04-03T10:14:59.697+0000] {standard_task_runner.py:100} ERROR - Failed to execute job 497 for task extract_generations (name 's3' is not defined; 3738)
[2023-04-03T10:14:59.709+0000] {local_task_job.py:208} INFO - Task exited with return code 1
[2023-04-03T10:14:59.720+0000] {taskinstance.py:2578} INFO - 0 downstream tasks scheduled from follow-on schedule check
