[2023-04-03T09:03:34.761+0000] {taskinstance.py:1083} INFO - Dependencies all met for <TaskInstance: pokeapi_dag.extract_pokemon scheduled__2023-04-02T00:00:00+00:00 [queued]>
[2023-04-03T09:03:34.765+0000] {taskinstance.py:1083} INFO - Dependencies all met for <TaskInstance: pokeapi_dag.extract_pokemon scheduled__2023-04-02T00:00:00+00:00 [queued]>
[2023-04-03T09:03:34.765+0000] {taskinstance.py:1279} INFO - 
--------------------------------------------------------------------------------
[2023-04-03T09:03:34.766+0000] {taskinstance.py:1280} INFO - Starting attempt 1 of 2
[2023-04-03T09:03:34.766+0000] {taskinstance.py:1281} INFO - 
--------------------------------------------------------------------------------
[2023-04-03T09:03:34.851+0000] {taskinstance.py:1300} INFO - Executing <Task(PythonOperator): extract_pokemon> on 2023-04-02 00:00:00+00:00
[2023-04-03T09:03:34.855+0000] {standard_task_runner.py:55} INFO - Started process 22789 to run task
[2023-04-03T09:03:34.856+0000] {standard_task_runner.py:82} INFO - Running: ['airflow', 'tasks', 'run', 'pokeapi_dag', 'extract_pokemon', 'scheduled__2023-04-02T00:00:00+00:00', '--job-id', '489', '--raw', '--subdir', 'DAGS_FOLDER/pokebase_to_s3.py', '--cfg-path', '/tmp/tmpamot017h']
[2023-04-03T09:03:34.857+0000] {standard_task_runner.py:83} INFO - Job 489: Subtask extract_pokemon
[2023-04-03T09:03:34.895+0000] {task_command.py:388} INFO - Running <TaskInstance: pokeapi_dag.extract_pokemon scheduled__2023-04-02T00:00:00+00:00 [running]> on host 59f4bcb29cab
[2023-04-03T09:03:34.952+0000] {taskinstance.py:1507} INFO - Exporting the following env vars:
AIRFLOW_CTX_DAG_OWNER=airflow
AIRFLOW_CTX_DAG_ID=pokeapi_dag
AIRFLOW_CTX_TASK_ID=extract_pokemon
AIRFLOW_CTX_EXECUTION_DATE=2023-04-02T00:00:00+00:00
AIRFLOW_CTX_TRY_NUMBER=1
AIRFLOW_CTX_DAG_RUN_ID=scheduled__2023-04-02T00:00:00+00:00
[2023-04-03T09:04:00.268+0000] {process_utils.py:129} INFO - Sending Signals.SIGTERM to group 22789. PIDs of all processes in the group: [22789]
[2023-04-03T09:04:00.268+0000] {process_utils.py:84} INFO - Sending the signal Signals.SIGTERM to group 22789
[2023-04-03T09:04:00.269+0000] {taskinstance.py:1479} ERROR - Received SIGTERM. Terminating subprocesses.
[2023-04-03T09:04:00.274+0000] {taskinstance.py:1768} ERROR - Task failed with exception
Traceback (most recent call last):
  File "/usr/local/lib/python3.10/site-packages/airflow/operators/python.py", line 175, in execute
    return_value = self.execute_callable()
  File "/usr/local/lib/python3.10/site-packages/airflow/operators/python.py", line 192, in execute_callable
    return self.python_callable(*self.op_args, **self.op_kwargs)
  File "/workspaces/data-engineer-zoomcamp-project/airflow/dags/pokebase_to_s3.py", line 47, in extract_pokemon
    response = requests.get(pokemon_url, timeout=1000)
  File "/usr/local/lib/python3.10/site-packages/requests/api.py", line 73, in get
    return request("get", url, params=params, **kwargs)
  File "/usr/local/lib/python3.10/site-packages/requests/api.py", line 59, in request
    return session.request(method=method, url=url, **kwargs)
  File "/usr/local/lib/python3.10/site-packages/requests/sessions.py", line 587, in request
    resp = self.send(prep, **send_kwargs)
  File "/usr/local/lib/python3.10/site-packages/requests/sessions.py", line 701, in send
    r = adapter.send(request, **kwargs)
  File "/usr/local/lib/python3.10/site-packages/requests/adapters.py", line 489, in send
    resp = conn.urlopen(
  File "/usr/local/lib/python3.10/site-packages/urllib3/connectionpool.py", line 703, in urlopen
    httplib_response = self._make_request(
  File "/usr/local/lib/python3.10/site-packages/urllib3/connectionpool.py", line 386, in _make_request
    self._validate_conn(conn)
  File "/usr/local/lib/python3.10/site-packages/urllib3/connectionpool.py", line 1042, in _validate_conn
    conn.connect()
  File "/usr/local/lib/python3.10/site-packages/urllib3/connection.py", line 419, in connect
    self.sock = ssl_wrap_socket(
  File "/usr/local/lib/python3.10/site-packages/urllib3/util/ssl_.py", line 449, in ssl_wrap_socket
    ssl_sock = _ssl_wrap_socket_impl(
  File "/usr/local/lib/python3.10/site-packages/urllib3/util/ssl_.py", line 493, in _ssl_wrap_socket_impl
    return ssl_context.wrap_socket(sock, server_hostname=server_hostname)
  File "/usr/local/lib/python3.10/ssl.py", line 513, in wrap_socket
    return self.sslsocket_class._create(
  File "/usr/local/lib/python3.10/ssl.py", line 1071, in _create
    self.do_handshake()
  File "/usr/local/lib/python3.10/ssl.py", line 1342, in do_handshake
    self._sslobj.do_handshake()
  File "/usr/local/lib/python3.10/site-packages/airflow/models/taskinstance.py", line 1481, in signal_handler
    raise AirflowException("Task received SIGTERM signal")
airflow.exceptions.AirflowException: Task received SIGTERM signal
[2023-04-03T09:04:00.288+0000] {taskinstance.py:1318} INFO - Marking task as UP_FOR_RETRY. dag_id=pokeapi_dag, task_id=extract_pokemon, execution_date=20230402T000000, start_date=20230403T090334, end_date=20230403T090400
[2023-04-03T09:04:00.307+0000] {standard_task_runner.py:100} ERROR - Failed to execute job 489 for task extract_pokemon (Task received SIGTERM signal; 22789)
[2023-04-03T09:04:00.321+0000] {process_utils.py:79} INFO - Process psutil.Process(pid=22789, status='terminated', exitcode=1, started='10:03:34') (22789) terminated with exit code 1
